Workbook

Sheet Sales_Data
A1: Date | B1: Product_Category | C1: Product_Name | D1: Units_Sold | E1: Unit_Price | F1: Revenue | G1: Payment_Method | I1: =SUM(F2:F128) -> 1298170
A2: 46023 | B2: Snacks | C2: Biscuits | D2: 200 | E2: 5 | F2: =D2*E2 -> 1000 | G2: M-Pesa
A3: 46023 | B3: Personal Care | C3: Petroleum Jelly | D3: 1000 | E3: 80 | F3: =D3*E3 -> 80000 | G3: Card
A4: 46023 | B4: Beverages | C4: Soda 500ml | D4: 500 | E4: 80 | F4: =D4*E4 -> 40000 | G4: M-Pesa
A5: 46024 | B5: Dairy | C5: Yogurt 250g | D5: 500 | E5: 70 | F5: =D5*E5 -> 35000 | G5: M-Pesa
A6: 46024 | B6: Personal Care | C6: Toothpaste | D6: 50 | E6: 120 | F6: =D6*E6 -> 6000 | G6: Card
A7: 46024 | B7: Beverages | C7: Water 1L | D7: 800 | E7: 50 | F7: =D7*E7 -> 40000 | G7: Cash
A8: 46025 | B8: Snacks | C8: Crisps | D8: 165 | E8: 50 | F8: =D8*E8 -> 8250 | G8: M-Pesa
A9: 46025 | B9: Dairy | C9: Milk 500ml | D9: 250 | E9: 60 | F9: =D9*E9 -> 15000 | G9: M-Pesa | I9: Row Labels | J9: Sum of Revenue
A10: 46025 | B10: Beverages | C10: Juice 1L | D10: 90 | E10: 150 | F10: =D10*E10 -> 13500 | G10: Card | I10: Bananas | J10: 16380
A11: 46026 | B11: Beverages | C11: Soda 500ml | D11: 120 | E11: 80 | F11: =D11*E11 -> 9600 | G11: Cash | I11: Biscuits | J11: 88210
A12: 46026 | B12: Dairy | C12: Milk 500ml | D12: 100 | E12: 60 | F12: =D12*E12 -> 6000 | G12: M-Pesa | I12: Body Wash | J12: 150400
A13: 46027 | B13: Dairy | C13: Yogurt 250g | D13: 170 | E13: 70 | F13: =D13*E13 -> 11900 | G13: Cash | I13: Crisps | J13: 45150
A14: 46028 | B14: Household | C14: Soap Bar | D14: 70 | E14: 40 | F14: =D14*E14 -> 2800 | G14: Card | I14: Detergent | J14: 59520
A15: 46029 | B15: Household | C15: Detergent | D15: 150 | E15: 120 | F15: =D15*E15 -> 18000 | G15: M-Pesa | I15: Juice 1L | J15: 211050
A16: 46030 | B16: Snacks | C16: Biscuits | D16: 260 | E16: 30 | F16: =D16*E16 -> 7800 | G16: Cash | I16: Milk 500ml | J16: 109260
A17: 46031 | B17: Snacks | C17: Crisps | D17: 290 | E17: 50 | F17: =D17*E17 -> 14500 | G17: Card | I17: Petroleum Jelly | J17: 80000
A18: 46032 | B18: Produce | C18: Bananas | D18: 320 | E18: 20 | F18: =D18*E18 -> 6400 | G18: M-Pesa | I18: Soap Bar | J18: 51240
A19: 46033 | B19: Produce | C19: Tomatoes | D19: 95 | E19: 30 | F19: =D19*E19 -> 2850 | G19: Cash | I19: Soda 500ml | J19: 141040
A20: 46034 | B20: Personal Care | C20: Toothpaste | D20: 50 | E20: 120 | F20: =D20*E20 -> 6000 | G20: Card | I20: Tomatoes | J20: 18270
A21: 46035 | B21: Personal Care | C21: Body Wash | D21: 100 | E21: 200 | F21: =D21*E21 -> 20000 | G21: M-Pesa | I21: Toothpaste | J21: 84120
... A24: 46038 | B24: Beverages | C24: Juice 1L | D24: 1000 | E24: 150 | F24: =D24*E24 -> 150000 | G24: M-Pesa | I24: Grand Total | J24: 1298170
A25: 46039 | B25: Dairy | C25: Milk 500ml | D25: 1300 | E25: 60 | F25: =D25*E25 -> 78000 | G25: Cash
A26: 46040 | B26: Dairy | C26: Yogurt 250g | D26: 600 | E26: 70 | F26: =D26*E26 -> 42000 | G26: Card
A27: 46041 | B27: Household | C27: Soap Bar | D27: 800 | E27: 40 | F27: =D27*E27 -> 32000 | G27: M-Pesa
A28: 46042 | B28: Household | C28: Detergent | D28: 220 | E28: 120 | F28: =D28*E28 -> 26400 | G28: Cash
A29: 46043 | B29: Snacks | C29: Biscuits | D29: 2500 | E29: 30 | F29: =D29*E29 -> 75000 | G29: Card | I29: REVENUE
A30: 46044 | B30: Snacks | C30: Crisps | D30: 280 | E30: 50 | F30: =D30*E30 -> 14000 | G30: M-Pesa | I30: =SUM(F2:F128) -> 1298170
A31: 46045 | B31: Produce | C31: Bananas | D31: 310 | E31: 20 | F31: =D31*E31 -> 6200 | G31: Cash
A32: 46046 | B32: Produce | C32: Tomatoes | D32: 304 | E32: 30 | F32: =D32*E32 -> 9120 | G32: Card
A33: 46047 | B33: Personal Care | C33: Toothpaste | D33: 370 | E33: 120 | F33: =D33*E33 -> 44400 | G33: M-Pesa
A34: 46048 | B34: Personal Care | C34: Body Wash | D34: 400 | E34: 200 | F34: =D34*E34 -> 80000 | G34: Cash
A35: 46049 | B35: Beverages | C35: Soda 500ml | D35: 430 | E35: 80 | F35: =D35*E35 -> 34400 | G35: Card
A36: 46050 | B36: Beverages | C36: Water 1L | D36: 600 | E36: 50 | F36: =D36*E36 -> 30000 | G36: M-Pesa
A37: 46051 | B37: Beverages | C37: Juice 1L | D37: 90 | E37: 150 | F37: =D37*E37 -> 13500 | G37: Cash
A38: 46052 | B38: Dairy | C38: Milk 500ml | D38: 120 | E38: 60 | F38: =D38*E38 -> 7200 | G38: Card
A39: 46053 | B39: Dairy | C39: Yogurt 250g | D39: 150 | E39: 70 | F39: =D39*E39 -> 10500 | G39: M-Pesa
A40: 46054 | B40: Household | C40: Soap Bar | D40: 180 | E40: 40 | F40: =D40*E40 -> 7200 | G40: Cash
A41: 46055 | B41: Household | C41: Detergent | D41: 21 | E41: 120 | F41: =D41*E41 -> 2520 | G41: Card
A42: 46056 | B42: Snacks | C42: Biscuits | D42: 24 | E42: 30 | F42: =D42*E42 -> 720 | G42: M-Pesa
...

Sheet Expense_Data
A1: Date | B1: Expense_Category | C1: Description | D1: Amount
A2: 46023 | B2: Rent | C2: Monthly Shop Rent | D2: 45000
A3: 46025 | B3: Utilities | C3: Electricity Bill | D3: 8500 | G3: Total Expense | H3: =SUM(D2:D54) -> 942900
A4: 46027 | B4: Transport | C4: Supplier Delivery | D4: 7200
A5: 46029 | B5: Inventory Purchase | C5: Beverage Stock Restock | D5: 28000
A6: 46031 | B6: Salaries | C6: Staff Salaries | D6: 65000 | H6: Column Labels
A7: 46033 | B7: Marketing | C7: Flyer Printing | D7: 4500 | H7: Inventory Purchase | I7: Marketing | J7: Rent | K7: Repairs | L7: Salaries | M7: Transport | N7: Utilities | O7: Grand Total
A8: 46035 | B8: Repairs | C8: Fridge Maintenance | D8: 6200 | G8: Sum of Amount | H8: 251500 | I8: 44100 | J8: 180000 | K8: 46900 | L8: 281500 | M8: 85800 | N8: 53100 | O8: 942900
A9: 46037 | B9: Transport | C9: Supplier Delivery | D9: 7600
A10: 46039 | B10: Inventory Purchase | C10: Dairy Stock Restock | D10: 24000
A11: 46041 | B11: Utilities | C11: Water Bill | D11: 3200
A12: 46043 | B12: Marketing | C12: Social Media Promotion | D12: 3500
A13: 46045 | B13: Transport | C13: Supplier Delivery | D13: 7400
A14: 46047 | B14: Inventory Purchase | C14: Snacks Stock Restock | D14: 18000
A15: 46049 | B15: Repairs | C15: Shelf Repair | D15: 4100
A16: 46051 | B16: Utilities | C16: Internet Bill | D16: 2800
A17: 46053 | B17: Salaries | C17: Staff Overtime Payment | D17: 8500
A18: 46054 | B18: Rent | C18: Monthly Shop Rent | D18: 45000
A19: 46056 | B19: Utilities | C19: Electricity Bill | D19: 8900
A20: 46058 | B20: Transport | C20: Supplier Delivery | D20: 7800
... A44: 46106 | B44: Inventory Purchase | C44: Snacks Stock Restock | D44: 21000
A45: 46108 | B45: Repairs | C45: Door Lock Replacement | D45: 3900 | G45: Row Labels | H45: Sum of Amount
A46: 46110 | B46: Utilities | C46: Internet Bill | D46: 3200 | G46: Inventory Purchase | H46: 251500
A47: 46112 | B47: Salaries | C47: Staff Overtime Payment | D47: 11000 | G47: Marketing | H47: 44100
A48: 46113 | B48: Rent | C48: Monthly Shop Rent | D48: 45000 | G48: Rent | H48: 180000
A49: 46117 | B49: Transport | C49: Supplier Delivery | D49: 10800 | G49: Repairs | H49: 46900
A50: 46122 | B50: Marketing | C50: Easter Promotion Campaign | D50: 9200 | G50: Salaries | H50: 281500
A51: 46127 | B51: Inventory Purchase | C51: Holiday Stock Restock | D51: 34000 | G51: Transport | H51: 85800
A52: 46132 | B52: Repairs | C52: Generator Repair | D52: 12500 | G52: Utilities | H52: 53100
A53: 46137 | B53: Utilities | C53: Electricity Bill | D53: 10100 | G53: Grand Total | H53: 942900
A54: 46142 | B54: Salaries | C54: Staff Salaries | D54: 67000

Sheet Inventory_Data
A1: Date | B1: Product_Name | C1: Opening_Stock | D1: Stock_Added | E1: Units_Sold | F1: Closing_Stock | G1: Reorder_Level | H1: Stock status
A2: 46023 | B2: Soda 500ml | C2: 120 | D2: 50 | E2: 35 | F2: =SUM(C2,D2)-E2 -> 135 | G2: 40 | H2: =IF(F2<=G2, "Reorder Needed", "Ok") -> Ok
A3: 46025 | B3: Water 1L | C3: 100 | D3: 40 | E3: 28 | F3: =SUM(C3,D3)-E3 -> 112 | G3: 35 | H3: =IF(F3<=G3, "Reorder Needed", "Ok") -> Ok
A4: 46027 | B4: Juice 1L | C4: 80 | D4: 30 | E4: 22 | F4: =SUM(C4,D4)-E4 -> 88 | G4: 25 | H4: =IF(F4<=G4, "Reorder Needed", "Ok") -> Ok
A5: 46029 | B5: Milk 500ml | C5: 90 | D5: 35 | E5: 30 | F5: =SUM(C5,D5)-E5 -> 95 | G5: 30 | H5: =IF(F5<=G5, "Reorder Needed", "Ok") -> Ok
A6: 46031 | B6: Yogurt 250g | C6: 75 | D6: 25 | E6: 18 | F6: =SUM(C6,D6)-E6 -> 82 | G6: 20 | H6: =IF(F6<=G6, "Reorder Needed", "Ok") -> Ok
A7: 46033 | B7: Soap Bar | C7: 110 | D7: 45 | E7: 26 | F7: =SUM(C7,D7)-E7 -> 129 | G7: 35 | H7: =IF(F7<=G7, "Reorder Needed", "Ok") -> Ok
A8: 46035 | B8: Detergent | C8: 70 | D8: 20 | E8: 15 | F8: =SUM(C8,D8)-E8 -> 75 | G8: 80 | H8: =IF(F8<=G8, "Reorder Needed", "Ok") -> Reorder Needed
A9: 46037 | B9: Biscuits | C9: 95 | D9: 30 | E9: 24 | F9: =SUM(C9,D9)-E9 -> 101 | G9: 30 | H9: =IF(F9<=G9, "Reorder Needed", "Ok") -> Ok
A10: 46039 | B10: Crisps | C10: 85 | D10: 25 | E10: 20 | F10: =SUM(C10,D10)-E10 -> 90 | G10: 25 | H10: =IF(F10<=G10, "Reorder Needed", "Ok") -> Ok
A11: 46041 | B11: Bananas | C11: 130 | D11: 40 | E11: 38 | F11: =SUM(C11,D11)-E11 -> 132 | G11: 150 | H11: =IF(F11<=G11, "Reorder Needed", "Ok") -> Reorder Needed
A12: 46043 | B12: Tomatoes | C12: 125 | D12: 35 | E12: 34 | F12: =SUM(C12,D12)-E12 -> 126 | G12: 45 | H12: =IF(F12<=G12, "Reorder Needed", "Ok") -> Ok
A13: 46045 | B13: Toothpaste | C13: 60 | D13: 20 | E13: 12 | F13: =SUM(C13,D13)-E13 -> 68 | G13: 15 | H13: =IF(F13<=G13, "Reorder Needed", "Ok") -> Ok
... A61: 46141 | B61: Crisps | C61: 64 | D61: 10 | E61: 31 | F61: =SUM(C61,D61)-E61 -> 43 | G61: 25 | H61: =IF(F61<=G61, "Reorder Needed", "Ok") -> Ok

Sheet Employee_Perfomance
A1: Employee_Name | B1: Month | C1: Days_Present | D1: Late_Arrivals | E1: Tasks_Completed | F1: Productivity_score
A2: Mary Wanjiku | B2: January | C2: 25 | D2: 1 | E2: 148 | F2: =E2/C2 -> 5.92
A3: Peter Kamau | B3: January | C3: 24 | D3: 2 | E3: 139 | F3: =E3/C3 -> 5.7916667
A4: Jane Njeri | B4: January | C4: 26 | D4: 0 | E4: 154 | F4: =E4/C4 -> 5.9230769
A5: Brian Otieno | B5: January | C5: 21 | D5: 6 | E5: 118 | F5: =E5/C5 -> 5.6190476
A6: Faith Achieng | B6: January | C6: 25 | D6: 1 | E6: 145 | F6: =E6/C6 -> 5.8
A7: Mary Wanjiku | B7: February | C7: 24 | D7: 2 | E7: 143 | F7: =E7/C7 -> 5.9583333
A8: Peter Kamau | B8: February | C8: 23 | D8: 3 | E8: 134 | F8: =E8/C8 -> 5.826087
A9: Jane Njeri | B9: February | C9: 25 | D9: 1 | E9: 150 | F9: =E9/C9 -> 6
A10: Brian Otieno | B10: February | C10: 20 | D10: 7 | E10: 110 | F10: =E10/C10 -> 5.5
A11: Faith Achieng | B11: February | C11: 24 | D11: 2 | E11: 140 | F11: =E11/C11 -> 5.8333333
A12: Mary Wanjiku | B12: March | C12: 25 | D12: 1 | E12: 151 | F12: =E12/C12 -> 6.04
A13: Peter Kamau | B13: March | C13: 24 | D13: 2 | E13: 141 | F13: =E13/C13 -> 5.875
... A21: Faith Achieng | B21: April | C21: 24 | D21: 2 | E21: 142 | F21: =E21/C21 -> 5.9166667

Sheet KPI Calculations
A1: KPI Name | B1: Value
A2: Total Revenue | B2: =SUM(Sales_Data!F2:F128) -> 1298170
A3: Total Expenses | B3: =SUM(Expense_Data!D2:D54) -> 942900
A4: Gross Profit | B4: =B2-B3 -> 355270
A5: Profit Margin % | B5: =B4/B2 -> 0.27366986 | E5: Row Labels | F5: Sum of Revenue
A6: Average Daily Sales | B6: =AVERAGE(Sales_Data!F2:F128) -> 10221.811 | E6: Beverages | F6: 491390
A7: Highest Revenue Category | B7: Beverages | E7: Dairy | F7: 213490
A8: Stockout Count | B8: =COUNTIF(Inventory_Data!H2:H61,"Reorder Needed") -> 2 | E8: Household | F8: 110760
A9: Average Attendance Rate % | B9: =AVERAGE(Employee_Perfomance!C2:C21)/26 -> 0.90769231 | E9: Personal Care | F9: 314520
A10: Average Late Arrivals | B10: =AVERAGE(Employee_Perfomance!D2:D21) -> 2.6 | E10: Produce | F10: 34650
A11: Lowest Inventory Product | B11: =INDEX(Inventory_Data!B2:B61,MATCH(MIN(Inventory_Data!F2:F61),Inventory_Data!F2:F61,0)) -> Crisps | E11: Snacks | F11: 133360
A12: Highest Expense Category | B12: Salaries | E12: Grand Total | F12: 1298170
